output/trades.csv
seq,price,qty,side
0,100,7,S
1,100,1,S
2,101,6,B
3,101,1,B
4,100,1,S
5,101,6,B
6,100,6,S
7,101,8,B
8,101,2,B
9,100,9,S
10,100,8,S
11,101,5,B
12,101,10,B
13,100,9,S
14,100,9,S
15,100,4,S
16,100,3,S
17,100,2,S
18,100,1,S
19,101,4,B
20,101,8,B
21,101,1,B
22,101,4,B
23,100,4,S
24,100,4,S
25,100,4,S
26,100,2,S
27,101,3,B
28,101,4,B
29,100,2,S
30,100,7,S
31,100,3,S
32,100,4,S
33,100,3,S
34,100,3,B
35,99,5,S
36,99,1,S
37,99,6,S
38,99,1,S
39,99,2,S
40,99,2,S
41,100,1,B
42,100,4,B
43,100,6,B
44,99,1,S
45,99,4,S
46,99,4,S
47,100,3,B
48,99,4,S
49,99,6,S
50,100,2,S
51,99,1,S
52,101,3,B
53,101,7,B
54,100,4,B
55,99,4,S
56,99,3,S
57,99,2,S
58,99,3,S
59,99,6,S
60,98,2,S
61,99,3,B
62,99,2,B
63,100,5,B
64,101,5,B
65,101,5,B
66,101,4,B
67,101,1,B
68,99,6,S
69,98,9,S
70,98,1,S
71,98,1,S
72,99,3,B
73,100,3,S
74,100,2,S
75,98,1,S
76,99,3,B
77,100,4,S
78,101,8,B
79,101,1,B
80,101,3,B
81,101,4,B
82,101,1,B
83,101,8,B
84,101,1,B
85,101,3,B
86,102,6,B
87,102,3,B
88,102,1,B
89,102,5,B
90,102,5,B
91,100,1,S
92,100,2,S
93,100,2,S
94,99,1,S
95,101,4,B
96,102,3,B
97,99,1,S
98,99,1,S
99,99,6,S
100,98,2,S
101,98,1,S
102,98,1,S
103,99,3,B
104,100,1,B
105,99,6,S
106,100,3,B
107,100,1,B
108,99,2,S
109,99,1,S
110,99,1,B
111,99,2,B
112,98,3,S
113,98,1,S
114,98,7,S
115,99,1,B
116,98,2,S
117,98,2,S
118,99,2,B
119,99,1,B
120,100,2,B
121,98,3,S
122,99,3,S
123,98,3,S
124,100,2,B
125,100,2,S
126,99,7,S
127,101,2,B
128,99,2,S
129,99,8,S
130,100,3,B
131,100,5,B
132,101,2,B
133,101,5,B
134,100,3,S
135,100,4,S
136,101,3,B
137,101,5,B
138,100,6,S
139,100,1,S
140,99,2,S
141,99,1,S
142,100,4,B
143,100,5,S
144,99,1,S
145,101,1,B
146,101,2,B
147,101,4,B
148,101,4,B
149,100,7,S
150,99,1,S
151,100,2,B
152,99,4,S
153,99,1,S
154,100,1,B
155,101,4,B
156,101,5,B
157,101,4,B
158,101,2,B
159,101,6,B
160,100,5,S
161,101,2,B
162,101,2,B
163,101,3,B
164,100,4,S
165,101,4,B
166,101,3,B
167,100,5,S
168,100,3,S
169,99,3,S
170,100,1,B
171,99,2,S
172,99,4,S
173,99,1,S
174,99,2,S
175,99,2,S
176,100,1,B
177,100,7,B
178,101,1,B
179,101,2,B
180,99,7,S
181,99,2,S
182,101,1,B
183,101,2,B
184,101,4,B
185,101,6,S
186,100,3,S
187,99,1,S
188,102,2,B
189,102,3,B
190,102,3,B
191,102,1,B
192,100,3,S
193,99,3,S
194,102,2,B
195,102,5,B
196,101,7,S
197,102,3,B
198,102,1,B
199,102,1,B
200,102,4,B
201,102,1,B
202,101,2,S
203,101,3,S
204,101,5,S
205,100,4,S
206,102,8,B
207,102,2,B
208,102,1,B
209,101,7,S
210,100,1,S
211,100,2,S
212,101,5,S
213,101,1,S
214,100,2,S
215,100,1,S
216,100,2,S
217,99,2,S
218,100,2,S
219,99,3,S
220,99,1,S
221,99,9,S
222,101,3,B
223,102,3,B
224,102,2,B
225,99,1,S
226,99,1,S
227,102,4,B
228,102,3,B
229,102,6,S
230,100,8,S
231,100,1,S
232,100,3,B
233,100,6,B
234,101,3,B
235,101,4,B
236,100,1,S
237,99,5,S
238,99,4,S
239,100,1,B
240,99,5,S
241,99,3,S
242,99,6,S
243,99,1,S
244,99,8,S
245,99,1,S
246,99,1,S
247,98,1,S
248,98,1,S
249,100,3,B
250,101,1,B
251,101,4,B
252,101,4,B
253,101,1,B
254,101,3,B
255,100,8,S
256,99,3,S
257,101,4,B
258,100,4,S
259,101,1,B
260,101,6,B
261,100,2,S
262,100,1,S
263,100,4,S
264,99,2,S
265,99,1,S
266,101,2,B
267,99,1,S
268,100,1,B
269,99,1,S
270,99,1,S
271,99,8,S
272,98,1,S
273,100,8,B
274,98,1,S
275,98,1,S
276,98,4,S
277,98,1,S
278,98,3,S
279,98,1,S
280,98,3,S
281,98,6,S
282,98,3,S
283,98,2,S
284,98,3,S
285,98,7,S
286,98,3,S
287,99,2,B
288,98,6,S
289,98,2,S
290,98,4,S
291,99,2,B
292,99,5,B
293,99,2,B
294,98,3,S
295,98,7,S
296,98,2,S
297,98,6,S
298,98,1,S
299,98,1,S
300,98,3,S
301,98,4,S
302,99,3,B
303,99,1,B
304,98,3,S
305,98,2,S
306,99,5,B
307,100,1,B
308,100,2,B
309,100,8,B
310,100,2,B
311,98,2,S
312,98,2,S
313,98,5,S
314,98,4,S
315,98,1,S
316,100,3,B
317,100,2,B
318,100,5,B
319,98,1,S
320,98,1,S
321,98,1,S
322,98,3,S
323,98,1,S
324,98,1,S
325,98,2,S
326,98,7,S
327,98,1,S
328,98,1,S
329,99,5,B
330,98,2,S
331,98,3,S
332,98,5,S
333,98,3,S
334,98,2,S
335,99,2,B
336,99,6,B
337,98,5,S
338,98,4,S
339,97,1,S
340,98,4,B
341,98,3,S
342,97,4,S
343,97,1,S
344,97,1,S
345,98,3,S
346,99,2,B
347,99,1,B
348,99,3,B
349,98,4,S
350,98,4,S
351,99,3,B
352,99,2,B
353,100,4,B
354,100,6,B
355,100,1,B
356,100,3,B
357,99,2,S
358,99,4,S
359,99,2,B
360,99,5,S
361,100,3,B
362,100,2,B
363,99,3,S
364,99,6,S
365,100,2,B
366,100,4,B
367,99,4,S
368,98,5,S
369,98,5,S
370,100,1,B
371,100,5,B
372,100,3,B
373,100,1,B
374,100,1,B
375,100,5,B
376,99,3,S
377,98,3,S
378,98,3,S
379,100,3,B
380,100,1,B
381,100,3,B
382,100,1,B
383,100,2,B
384,98,4,S
385,98,5,S
386,98,1,S
387,100,3,B
388,100,2,B
389,100,7,B
390,99,5,S
391,99,2,B
392,100,1,B
393,100,3,B
394,100,2,B
395,100,2,B
396,100,6,B
397,98,2,S
398,98,1,S
399,97,5,S
400,97,2,S
401,97,7,S
402,98,3,B
403,100,1,B
404,101,1,B
405,101,5,B
406,101,2,B
407,100,4,S
408,101,5,B
409,100,5,S
410,99,2,S
411,99,3,S
412,99,7,S
413,99,3,S
414,97,3,S
415,97,1,S
416,97,3,S
417,97,3,S
418,97,3,S
419,97,2,S
420,99,6,B
421,99,4,S
422,99,6,B
423,99,1,S
424,97,3,S
425,97,1,S
426,97,4,S
427,99,3,S
428,98,4,B
429,98,4,S
430,98,2,S
431,97,3,S
432,97,2,S
433,100,4,B
434,100,3,B
435,99,1,S
436,99,1,S
437,97,2,S
438,97,3,S
439,97,2,S
440,97,3,S
441,97,1,S
442,97,2,S
443,97,1,S
444,97,1,S
445,97,1,S
446,97,1,S
447,97,5,S
448,97,1,S
449,97,6,S
450,97,2,S
451,97,4,S
452,97,3,S
453,97,4,S
454,97,6,S
455,97,2,S
456,97,1,S
457,97,1,S
458,97,6,S
459,97,3,S
460,98,5,B
461,98,5,B
462,97,7,S
463,97,1,S
464,98,3,B
465,97,1,S
466,99,2,B
467,99,1,B
468,99,2,B
469,98,1,S
470,99,3,B
471,100,7,B
472,100,3,B
473,100,6,B
474,100,1,B
475,101,4,B
476,99,5,S
477,99,4,S
478,98,5,S
479,99,1,B
480,98,1,S
481,99,5,B
482,99,5,B
483,98,3,S
484,98,1,S
485,97,1,S
486,99,5,B
487,99,5,B
488,99,4,B
489,99,6,S
490,98,2,S
491,98,2,S
492,98,4,S
493,97,2,S
494,97,3,S
495,100,3,B
496,100,4,B
497,100,4,B
498,100,5,B
499,100,2,B
500,100,6,B
501,100,1,S
502,100,1,S
503,98,1,S
504,97,2,S
505,99,3,B
506,99,1,B
507,98,8,S
508,99,1,B
509,99,6,B
510,98,6,S
511,98,1,S
512,97,1,S
513,97,1,S
514,99,4,B
515,100,5,B
516,100,1,B
517,97,3,S
518,97,1,S
519,97,2,S
520,99,9,S
521,100,2,B
522,100,3,B
523,99,1,S
524,98,3,S
525,99,1,B
526,100,3,B
527,100,3,B
528,100,1,B
529,100,1,S
530,99,3,S
531,101,2,B
532,101,1,B
533,99,7,S
534,99,2,S
535,99,4,S
536,99,2,S
537,99,2,S
538,99,1,S
539,99,1,S
540,99,8,S
541,100,3,B
542,101,2,B
543,100,2,S
544,99,1,S
545,99,2,S
546,99,5,S
547,100,1,B
548,100,1,B
549,101,3,B
550,99,1,S
551,101,1,B
552,101,1,B
553,101,4,B
554,101,5,B
555,101,2,B
556,100,8,S
557,100,2,S
558,101,1,B
559,101,2,B
560,99,3,S
561,98,1,S
562,99,5,B
563,100,2,S
564,99,2,B
565,98,2,S
566,98,3,S
567,97,2,S
568,98,7,S
569,98,2,S
570,97,3,S
571,97,2,S
572,98,5,S
573,97,5,S
574,97,3,S
575,97,1,S
576,98,1,B
577,98,1,B
578,98,1,B
579,98,4,S
580,98,1,S
581,97,1,S
582,97,5,S
583,97,3,S
584,97,6,S
585,98,3,B
586,99,1,B
587,98,5,S
588,98,1,S
589,98,5,S
590,98,2,S
591,98,7,S
592,97,2,S
593,99,4,B
594,99,3,B
595,98,4,B
596,98,2,B
597,99,4,B
598,99,3,B
599,99,1,B
600,99,1,B
601,99,2,S
602,100,2,B
603,99,3,S
604,99,1,S
605,99,4,S
606,99,1,B
607,100,3,B
608,100,6,B
609,99,3,S
610,98,2,S
611,98,5,S
612,99,2,B
613,98,1,S
614,98,7,S
615,97,2,S
616,97,5,S
617,99,2,B
618,99,5,B
619,99,1,B
620,100,2,B
621,100,4,B
622,100,4,B
623,99,3,S
624,99,4,S
625,99,6,S
626,100,6,B
627,100,2,B
628,99,2,S
629,99,8,S
630,100,4,B
631,99,2,S
632,99,6,S
633,98,1,S
634,98,4,S
635,98,4,S
636,98,5,S
637,99,2,B
638,99,1,S
639,98,1,S
640,100,2,B
641,100,1,B
642,100,2,B
643,100,3,S
644,99,4,S
645,101,3,B
646,100,4,S
647,101,1,B
648,101,3,B
649,101,4,B
650,100,3,S
651,99,4,S
652,99,1,S
653,99,2,S
654,100,1,B
655,100,3,S
656,100,1,S
657,100,1,S
658,99,5,S
659,99,3,B
660,99,3,B
661,100,2,S
662,98,1,S
663,98,5,S
664,97,3,S
665,97,1,S
666,99,8,B
667,97,9,S
668,97,2,S
669,97,3,S
670,97,1,S
671,97,3,S
672,97,3,S
673,97,3,S
674,97,1,S
675,97,5,S
676,101,1,B
677,101,1,B
678,100,3,S
679,100,2,S
680,100,1,S
681,101,4,B
682,101,2,B
683,101,3,B
684,101,4,B
685,101,1,B
686,101,4,B
687,101,3,B
688,101,2,B
689,101,1,B
690,100,7,S
691,101,4,B
692,101,4,B
693,101,1,B
694,101,6,B
695,101,2,B
696,101,1,B
697,101,5,B
698,101,3,B
699,100,2,S
700,100,4,S
701,100,6,S
702,100,2,S
703,100,4,S
704,100,5,S
705,101,4,B
706,101,6,B
